{"name": "test_failure", "status": "failed", "statusDetails": {"message": "AssertionError: assert False", "trace": "def test_failure():\n        \"\"\"this test fails\"\"\"\n>       assert False\nE       assert False\n\ntestcases\\test_demo.py:20: AssertionError"}, "description": "this test fails", "start": 1663577778692, "stop": 1663577778693, "uuid": "889d822f-1c3e-4fdf-8d5f-439b02c717bc", "historyId": "044325bb1ab997cc19a0104f02d9e56a", "testCaseId": "be0cac94cedf6a44a1579268c12b9b95", "fullName": "testcases.test_demo#test_failure", "labels": [{"name": "parentSuite", "value": "testcases"}, {"name": "suite", "value": "test_demo"}, {"name": "host", "value": "SHANB-057776"}, {"name": "thread", "value": "19300-MainThread"}, {"name": "framework", "value": "pytest"}, {"name": "language", "value": "cpython3"}, {"name": "package", "value": "testcases.test_demo"}]}